Workbook

Sheet Cover
A1: Whirlpool Corporation (WHR) — Credit Analysis: $2.0B ABL Participation Request
A2: Prepared by Taruni Komma | Data as of October 2026 | Financials through June 30, 2026
A4: REQUEST AND RECOMMENDATION
A5: Request | B5: $150mm participation in Whirlpool's $2.0B senior secured asset-based revolving credit facility
A6: Recommendation | B6: Approve the secured ABL participation with conditions; do not extend unsecured credit
A7: Obligor risk rating | B7: ='Risk Rating'!B14&" — "&'Risk Rating'!C14 -> 7 — Special mention
A8: ABL facility risk rating | B8: ='Risk Rating'!B16&" — "&'Risk Rating'!C16 -> 6 — Pass — watch
A10: KEY METRICS
A11: LTM net sales ($mm) | B11: =Financials!G6 -> 14921
A12: LTM EBITDA ($mm) | B12: ='Credit Metrics'!E6 -> 781
A13: LTM EBITDA margin | B13: ='Credit Metrics'!E7 -> 0.052342336
A14: Net debt / EBITDA (LTM) | B14: ='Credit Metrics'!E14 -> 7.4635083
A15: EBITDA / interest (LTM) | B15: ='Credit Metrics'!E18 -> 2.4637224
A16: Run-rate coverage after refinancing | B16: ='Capital Structure'!E17 -> 1.8686893
A17: Base case net debt / EBITDA, FY2028E | B17: =Projections!E28 -> 4.5725217
A18: Stress case net debt / EBITDA, FY2028E | B18: =Projections!E62 -> 7.9937455
A19: Estimated ABL borrowing base ($mm) | B19: ='ABL Collateral'!G8 -> 1453.4949
A20: Springing covenant trigger: availability below ($mm) | B20: ='ABL Collateral'!B12 -> 145.34949
A22: WORKBOOK
A23: • Financials — reported spreads FY2023–FY2025, H1 2025/2026 and LTM June 2026
A24: • Credit Metrics — leverage, coverage, cash flow ratios and the legacy 3.0x covenant test
A25: • Capital Structure — pro forma debt stack after the June 2026 refinancing, bond prices, ratings
A26: • Projections — base and stress cases with leverage, coverage and the ABL springing FCCR test
A27: • ABL Collateral — borrowing base estimate and collateral coverage
A28: • Risk Rating — weighted scorecard, obligor rating and collateral-notched facility rating
A29: • Sources — every filing and data page used
A31: COLOR LEGEND
A32: Blue text — reported figure or assumption
A33: Black text — formula
A34: Green text — link to another sheet
A35: Yellow fill — key assumption

Sheet Financials
A1: Whirlpool Corporation — Financial Spreads ($ millions)
A2: Fiscal year = calendar year. LTM = FY2025 − H1 2025 + H1 2026 for flow items. Blue = reported figures (sources in comments and on the Sources sheet).
A4: ($ in millions) | B4: FY2023A | C4: FY2024A | D4: FY2025A | E4: H1 2025 | F4: H1 2026 | G4: LTM Jun-26
A5: INCOME STATEMENT & CASH FLOW
A6: Net sales | B6: 19455 | C6: 16607 | D6: 15524 | E6: 7393 | F6: 6790 | G6: =D6-E6+F6 -> 14921
A7: Operating profit (GAAP) | B7: 1015 | C7: 143 | D7: 838 | E7: 389 | F7: 181 | G7: =D7-E7+F7 -> 630
A8: Ongoing EBIT (company-adjusted) | B8: 1191 | C8: 887 | D8: 729 | E8: 414 | F8: 106 | G8: =D8-E8+F8 -> 421
A9: Depreciation & amortization | B9: 361 | C9: 333 | D9: 338 | E9: 163 | F9: 185 | G9: =D9-E9+F9 -> 360
A10: Interest expense | B10: 351 | C10: 358 | D10: 341 | E10: 164 | F10: 140 | G10: =D10-E10+F10 -> 317
A11: Income tax expense | B11: 77 | C11: 10 | D11: 142
A12: Net earnings available to Whirlpool | B12: 481 | C12: -323 | D12: 318
A13: Cash from operating activities | B13: 915 | C13: 835 | D13: 467 | E13: -702 | F13: -947 | G13: =D13-E13+F13 -> 222
A14: Capital expenditures | B14: 549 | C14: 451 | D14: 389 | E14: 154 | F14: 162 | G14: =D14-E14+F14 -> 397
A15: Dividends paid | B15: 384 | C15: 384 | D15: 299
A16: Free cash flow (CFO − capex) | B16: =B13-B14 -> 366 | C16: =C13-C14 -> 384 | D16: =D13-D14 -> 78 | E16: =E13-E14 -> -856 | F16: =F13-F14 -> -1109 | G16: =G13-G14 -> -175
A18: BALANCE SHEET (period end)
A19: Cash and cash equivalents | B19: 1570 | C19: 1275 | D19: 669 | G19: 1239 | H19: Jun-26 includes $212mm restricted for the July 1, 2026 debt payment
A20: Notes payable | B20: 17 | C20: 18 | D20: 351 | G20: 16
A21: Current maturities of long-term debt | B21: 800 | C21: 1850 | D21: 586 | G21: 212
A22: Long-term debt | B22: 6414 | C22: 4758 | D22: 5583 | G22: 6840
A23: Lease liabilities (noncurrent) | B23: 612 | C23: 711 | D23: 669 | G23: =D23 -> 669 | H23: Jun-26 not disclosed in release; Dec-25 carried forward
A24: Total stockholders' equity | B24: 2537 | C24: 2933 | D24: 2715 | G24: 3923
A25: Accounts receivable, net | B25: 1529 | C25: 1317 | D25: 1276 | G25: =D25 -> 1276 | H25: Jun-26 not disclosed in release; Dec-25 carried forward
A26: Inventories | B26: 2247 | C26: 2035 | D26: 2307 | G26: =D26 -> 2307 | H26: Jun-26 not disclosed in release; Dec-25 carried forward
A27: Property, net | B27: 2234 | C27: 2275 | D27: 2194 | G27: =D27 -> 2194 | H27: Jun-26 not disclosed in release; Dec-25 carried forward
A28: Accounts payable | B28: 3598 | C28: 3530 | D28: 3704 | G28: =D28 -> 3704 | H28: Jun-26 not disclosed in release; Dec-25 carried forward
A29: Total debt (notes payable + current + long-term) | B29: =B20+B21+B22 -> 7231 | C29: =C20+C21+C22 -> 6626 | D29: =D20+D21+D22 -> 6520 | G29: =G20+G21+G22 -> 7068
A31: Notes: H1 columns cover six months ended June 30. Balance sheet LTM column shows June 30, 2026.
A32: Ongoing EBIT is Whirlpool's non-GAAP measure (excludes restructuring, impairments, M&A and legal items).
A33: FY2024 company-reported free cash flow was $385mm; this sheet computes CFO − capex = $384mm (rounding).

Sheet Credit Metrics
A1: Credit Metrics and Covenant Test
A2: EBITDA = ongoing EBIT + D&A. LTM = twelve months ended June 30, 2026.
A4: Metric | B4: FY2023A | C4: FY2024A | D4: FY2025A | E4: LTM Jun-26 | F4: Bank guideline (illustrative)
A5: PROFITABILITY
A6: EBITDA ($mm) | B6: =Financials!B8+Financials!B9 -> 1552 | C6: =Financials!C8+Financials!C9 -> 1220 | D6: =Financials!D8+Financials!D9 -> 1067 | E6: =Financials!G8+Financials!G9 -> 781
A7: EBITDA margin | B7: =B6/Financials!B6 -> 0.079773837 | C7: =C6/Financials!C6 -> 0.073462998 | D7: =D6/Financials!D6 -> 0.068732285 | E7: =E6/Financials!G6 -> 0.052342336
A8: Ongoing EBIT margin | B8: =Financials!B8/Financials!B6 -> 0.061218196 | C8: =Financials!C8/Financials!C6 -> 0.053411212 | D8: =Financials!D8/Financials!D6 -> 0.046959547 | E8: =Financials!G8/Financials!G6 -> 0.028215267
A9: LEVERAGE
A10: Total debt ($mm) | B10: =Financials!B29 -> 7231 | C10: =Financials!C29 -> 6626 | D10: =Financials!D29 -> 6520 | E10: =Financials!G29 -> 7068
A11: Net debt ($mm) | B11: =Financials!B29-Financials!B19 -> 5661 | C11: =Financials!C29-Financials!C19 -> 5351 | D11: =Financials!D29-Financials!D19 -> 5851 | E11: =Financials!G29-Financials!G19 -> 5829
A12: Lease-adjusted debt ($mm) | B12: =Financials!B29+Financials!B23 -> 7843 | C12: =Financials!C29+Financials!C23 -> 7337 | D12: =Financials!D29+Financials!D23 -> 7189 | E12: =Financials!G29+Financials!G23 -> 7737
A13: Total debt / EBITDA | B13: =B10/B6 -> 4.6591495 | C13: =C10/C6 -> 5.4311475 | D13: =D10/D6 -> 6.1105904 | E13: =E10/E6 -> 9.049936 | F13: ≤ 3.5x
A14: Net debt / EBITDA | B14: =B11/B6 -> 3.6475515 | C14: =C11/C6 -> 4.3860656 | D14: =D11/D6 -> 5.4835989 | E14: =E11/E6 -> 7.4635083 | F14: ≤ 3.0x
A15: Lease-adjusted debt / EBITDA | B15: =B12/B6 -> 5.0534794 | C15: =C12/C6 -> 6.0139344 | D15: =D12/D6 -> 6.737582 | E15: =E12/E6 -> 9.9065301 | F15: ≤ 4.0x
A16: Debt / total capital | B16: =B10/(B10+Financials!B24) -> 0.74027437 | C16: =C10/(C10+Financials!C24) -> 0.69316874 | D16: =D10/(D10+Financials!D24) -> 0.70600975 | E16: =E10/(E10+Financials!G24) -> 0.6430716 | F16: ≤ 60%
A17: COVERAGE & CASH FLOW
A18: EBITDA / interest expense | B18: =B6/Financials!B10 -> 4.4216524 | C18: =C6/Financials!C10 -> 3.4078212 | D18: =D6/Financials!D10 -> 3.1290323 | E18: =E6/Financials!G10 -> 2.4637224 | F18: ≥ 3.0x
A19: Ongoing EBIT / interest expense | B19: =Financials!B8/Financials!B10 -> 3.3931624 | C19: =Financials!C8/Financials!C10 -> 2.4776536 | D19: =Financials!D8/Financials!D10 -> 2.1378299 | E19: =Financials!G8/Financials!G10 -> 1.3280757 | F19: ≥ 2.0x
A20: Cash from operations / total debt | B20: =Financials!B13/B10 -> 0.12653851 | C20: =Financials!C13/C10 -> 0.12601871 | D20: =Financials!D13/D10 -> 0.071625767 | E20: =Financials!G13/E10 -> 0.031409168 | F20: ≥ 15%
A21: Free cash flow / total debt | B21: =Financials!B16/B10 -> 0.050615406 | C21: =Financials!C16/C10 -> 0.057953516 | D21: =Financials!D16/D10 -> 0.01196319 | E21: =Financials!G16/E10 -> -0.024759479 | F21: ≥ 5%
A22: LEGACY REVOLVER COVENANT (interest coverage ≥ 3.0x, tested quarterly on a rolling four-quarter basis)
A23: Covenant minimum | B23: 3 | C23: 3 | D23: 3 | E23: 3
A24: Headroom vs. covenant | B24: =B18/B23-1 -> 0.47388414 | C24: =C18/C23-1 -> 0.13594041 | D24: =D18/D23-1 -> 0.043010753 | E24: =E18/E23-1 -> -0.1787592
A25: Status (EBITDA / interest proxy) | B25: =IF(B18>=B23,"Pass","Breach") -> Pass | C25: =IF(C18>=C23,"Pass","Breach") -> Pass | D25: =IF(D18>=D23,"Pass","Breach") -> Pass | E25: =IF(E18>=E23,"Pass","Breach") -> Breach
A27: Covenant proxy: the credit agreement's own EBITDA and interest definitions may differ. The May 2026 amendment excluded the March 31, 2026 quarter from the test and required the facility to be refinanced before July 1, 2026; it was replaced by the ABL on June 16, 2026 (Q1 2026 10-Q; 8-K).
A28: Bank guideline column shows illustrative thresholds for a pass-rated corporate borrower, for comparison only.

Sheet Capital Structure
A1: Pro Forma Capital Structure — After the June 2026 Refinancing
A2: Debt at June 30, 2026, less the $212mm repaid on July 1, 2026 from restricted cash. Market prices and yields as of Oct 15, 2026.
A4: Instrument | B4: Security | C4: Rate | D4: Maturity | E4: Principal ($mm) | F4: Annual interest ($mm) | G4: Price | H4: Yield to worst
A5: $2.0B asset-based revolving loan (ABL) | B5: 1st lien (A/R, inventory, M&E, IP) | C5: SOFR + 1.50–2.00% | D5: Jun 2031 | E5: Drawn amount within other debt
A6: 7.500% senior secured notes | B6: 2nd lien | C6: 0.075 | D6: Jul 1, 2031 | E6: 1000 | F6: =E6*C6 -> 75
A7: 7.875% senior secured notes | B7: 2nd lien | C7: 0.07875 | D7: Jul 1, 2034 | E7: 1000 | F7: =E7*C7 -> 78.75 | G7: 88.664 | H7: 0.1
A8: 4.750% senior notes | B8: Unsecured | C8: 0.0475 | D8: Feb 26, 2029 | E8: 700 | F8: =E8*C8 -> 33.25 | G8: 91.845 | H8: 0.0863
A9: 6.125% senior notes | B9: Unsecured | C9: 0.06125 | D9: Jun 15, 2030 | E9: 600 | F9: =E9*C9 -> 36.75 | G9: 86.416 | H9: 0.1069
A10: 6.500% senior notes | B10: Unsecured | C10: 0.065 | D10: Jun 15, 2033 | E10: 600 | F10: =E10*C10 -> 39 | G10: 76.065 | H10: 0.1177
A11: ABL borrowings, legacy notes and other facilities | B11: Mixed | C11: 0.0525 | D11: Various | E11: =E13-SUM(E5:E10) -> 2956 | F11: =E11*C11 -> 155.19 | I11: Residual to reported total. Blended rate is an assumption: legacy notes at ~4–5.75% coupons and ABL draws at ~SOFR + 1.75%
A13: Total pro forma debt | C13: =F13/E13 -> 0.060959743 | E13: =Financials!G29-Financials!G21 -> 6856 | F13: =SUM(F5:F11) -> 417.94 | I13: Rate column = weighted average cost of debt
A14: Pro forma cash | E14: =Financials!G19-Financials!G21 -> 1027
A15: Pro forma net debt | E15: =E13-E14 -> 5829
A16: Secured debt ahead of unsecured notes (2nd lien notes only) | E16: =E6+E7 -> 2000
A17: Run-rate interest coverage (LTM EBITDA / pro forma interest) | E17: ='Credit Metrics'!E6/F13 -> 1.8686893
A18: Pro forma net debt / LTM EBITDA | E18: =E15/'Credit Metrics'!E6 -> 7.4635083
A20: CREDIT RATINGS
A21: Agency | B21: Current rating | C21: Recent actions
A22: Moody's | B22: Ba3 | C22: Baa3 → Ba1 (Apr 29, 2025, negative outlook); → Ba2 (Feb 2026); Ba3 as of Jun 5, 2026
A23: S&P Global | B23: BB | C23: Downgraded to BB, negative outlook (Dec 15, 2025): adjusted leverage ~6x, refinancing needs
A24: Fitch | B24: BB | C24: BBB- → BB+ (May 5, 2025, negative outlook); BB as of Jun 5, 2026
A26: All three agencies rate Whirlpool below investment grade. Bond yields of 8.6%–11.8% price in single-B-like risk on the unsecured notes.

Sheet Projections
A1: Projections — Base Case vs. Stress Case
A2: Base case follows management's updated FY2026 guidance (sales ≈ $15.0B, ongoing EBIT ≈ $630mm, CFO ≈ $700mm). Stress case assumes a prolonged U.S. housing and appliance downturn. Blue = assumption.
A4: BASE CASE — management guidance, gradual margin recovery
A5: ($ in millions) | B5: FY2025A | C5: FY2026E | D5: FY2027E | E5: FY2028E
A6: Net sales growth | C6: -0.034 | D6: 0.02 | E6: 0.03
A7: Ongoing EBIT margin | B7: ='Credit Metrics'!D8 -> 0.046959547 | C7: 0.042 | D7: 0.05 | E7: 0.055
A8: Depreciation & amortization | B8: =Financials!D9 -> 338 | C8: 370 | D8: 375 | E8: 380
A9: Capital expenditures | B9: =Financials!D14 -> 389 | C9: 400 | D9: 425 | E9: 425
A10: Working capital release / (build) | C10: 150 | D10: 0 | E10: 0
A11: Restructuring and other cash costs | C11: -50 | D11: -25 | E11: 0
A12: Dividends ($0.90 per quarter × ~56mm shares) | B12: =Financials!D15 -> 299 | C12: 202 | D12: 202 | E12: 202
A13: Cash tax rate on pretax income | C13: 0.25 | D13: 0.25 | E13: 0.25
A14: Rate on incremental borrowing | C14: 0.0625 | D14: 0.0625 | E14: 0.0625
A15: Minimum cash balance | C15: 700 | D15: 700 | E15: 700
A17: Net sales | B17: =Financials!D6 -> 15524 | C17: =B17*(1+C6) -> 14996.184 | D17: =C17*(1+D6) -> 15296.108 | E17: =D17*(1+E6) -> 15754.991
A18: Ongoing EBIT | B18: =Financials!D8 -> 729 | C18: =C17*C7 -> 629.83973 | D18: =D17*D7 -> 764.80538 | E18: =E17*E7 -> 866.5245
A19: EBITDA | B19: ='Credit Metrics'!D6 -> 1067 | C19: =C18+C8 -> 999.83973 | D19: =D18+D8 -> 1139.8054 | E19: =E18+E8 -> 1246.5245
A20: Interest expense | B20: =Financials!D10 -> 341 | C20: =Financials!F10+'Capital Structure'!$F$13/2 -> 348.97 | D20: ='Capital Structure'!$F$13+D14*MAX(0,C26-'Capital Structure'!$E$15) -> 417.94 | E20: ='Capital Structure'!$F$13+E14*MAX(0,D26-'Capital Structure'!$E$15) -> 417.94
A21: Pretax income (ongoing) | C21: =C18-C20 -> 280.86973 | D21: =D18-D20 -> 346.86538 | E21: =E18-E20 -> 448.5845
A22: Cash taxes | C22: =MAX(0,C21*C13) -> 70.217432 | D22: =MAX(0,D21*D13) -> 86.716346 | E22: =MAX(0,E21*E13) -> 112.14613
A23: Cash from operations | C23: =C19-C20-C22+C10+C11 -> 680.6523 | D23: =D19-D20-D22+D10+D11 -> 610.14904 | E23: =E19-E20-E22+E10+E11 -> 716.43838
A24: Free cash flow | B24: =Financials!D16 -> 78 | C24: =C23-C9 -> 280.6523 | D24: =D23-D9 -> 185.14904 | E24: =E23-E9 -> 291.43838
A25: Free cash flow after dividends | C25: =C24-C12 -> 78.652296 | D25: =D24-D12 -> -16.850962 | E25: =E24-E12 -> 89.438375
A26: Net debt (year end) | B26: ='Credit Metrics'!D11 -> 5851 | C26: =B26-C25 -> 5772.3477 | D26: =C26-D25 -> 5789.1987 | E26: =D26-E25 -> 5699.7603
A27: Total debt (net debt + minimum cash) | C27: =C26+C15 -> 6472.3477 | D27: =D26+D15 -> 6489.1987 | E27: =E26+E15 -> 6399.7603
A28: Net debt / EBITDA | B28: ='Credit Metrics'!D14 -> 5.4835989 | C28: =C26/C19 -> 5.773273 | D28: =D26/D19 -> 5.0791115 | E28: =E26/E19 -> 4.5725217
A29: Total debt / EBITDA | C29: =C27/C19 -> 6.4733852 | D29: =D27/D19 -> 5.6932515 | E29: =E27/E19 -> 5.134083
A30: EBITDA / interest | B30: ='Credit Metrics'!D18 -> 3.1290323 | C30: =C19/C20 -> 2.8651166 | D30: =D19/D20 -> 2.7271986 | E30: =E19/E20 -> 2.9825441
A31: Fixed charge coverage (ABL definition, approx.) | C31: =(C19-C9-C22-C12)/C20 -> 0.93882654 | D31: =(D19-D9-D22-D12)/D20 -> 1.0194981 | E31: =(E19-E9-E22-E12)/E20 -> 1.2139981
A32: ABL springing FCCR test (≥ 1.0x) | C32: =IF(C31>=1,"Pass","Fail") -> Fail | D32: =IF(D31>=1,"Pass","Fail") -> Pass | E32: =IF(E31>=1,"Pass","Fail") -> Pass
A33: Legacy 3.0x interest coverage test (reference) | C33: =IF(C30>=3,"Pass","Below 3.0x") -> Below 3.0x | D33: =IF(D30>=3,"Pass","Below 3.0x") -> Below 3.0x | E33: =IF(E30>=3,"Pass","Below 3.0x") -> Below 3.0x
A34: Free cash flow / total debt | C34: =C24/C27 -> 0.043361746 | D34: =D24/D27 -> 0.02853188 | E34: =E24/E27 -> 0.045538952
A38: STRESS CASE — sales −5% then −3%, EBIT margin stuck at 2.5–3.0%, dividend maintained
A39: ($ in millions) | B39: FY2025A | C39: FY2026E | D39: FY2027E | E39: FY2028E
A40: Net sales growth | C40: -0.053 | D40: -0.03 | E40: 0
A41: Ongoing EBIT margin | B41: ='Credit Metrics'!D8 -> 0.046959547 | C41: 0.025 | D41: 0.025 | E41: 0.03
A42: Depreciation & amortization | B42: =Financials!D9 -> 338 | C42: 370 | D42: 375 | E42: 380
A43: Capital expenditures | B43: =Financials!D14 -> 389 | C43: 350 | D43: 325 | E43: 325
A44: Working capital release / (build) | C44: 100 | D44: 0 | E44: 0
A45: Restructuring and other cash costs | C45: -75 | D45: -50 | E45: -25
...

Sheet ABL Collateral
A1: ABL Borrowing Base Estimate
A2: Estimate from December 31, 2025 balances; the actual borrowing base is set by field exams and appraisals and moves with seasonal working capital. Intellectual property is excluded here to stay conservative.
A4: Collateral | B4: Book value ($mm) | C4: Share in US & Canada borrowers | D4: Eligible % | E4: Recovery value % | F4: Advance rate | G4: Borrowing base ($mm)
A5: Accounts receivable | B5: =Financials!D25 -> 1276 | C5: 0.65 | D5: 0.85 | E5: 1 | F5: 0.85 | G5: =B5*C5*D5*E5*F5 -> 599.2415
A6: Inventory (net orderly liquidation value) | B6: =Financials!D26 -> 2307 | C6: 0.65 | D6: 0.8 | E6: 0.6 | F6: 0.85 | G6: =B6*C6*D6*E6*F6 -> 611.8164
A7: Machinery & equipment (orderly liquidation value) | B7: =Financials!D27 -> 2194 | C7: 0.65 | D7: 0.5 | E7: 0.4 | F7: 0.85 | G7: =B7*C7*D7*E7*F7 -> 242.437
A8: Estimated borrowing base | G8: =SUM(G5:G7) -> 1453.4949
A10: ABL commitment | B10: 2000
A11: Line cap (lower of commitment and borrowing base) | B11: =MIN(B10,G8) -> 1453.4949
A12: Springing FCCR trigger: availability below | B12: =MAX(10%*B11,135) -> 145.34949
A13: Collateral recovery value / line cap (before advance rates) | B13: =SUMPRODUCT(B5:B7,C5:C7,D5:D7,E5:E7)/B11 -> 1.1764706
A14: Proposed bank commitment (participation) | B14: 150
A15: Bank share of facility | B15: =B14/B10 -> 0.075
A17: Advance rates and liquidation values are typical ABL market assumptions, not facility terms.
A18: US & Canada share of assets is an assumption based on MDA North America being roughly two-thirds of sales.
A19: Facility terms (8-K, June 16, 2026): first-priority lien; SOFR + 1.50–2.00% based on availability; springing FCCR ≥ 1.00x when availability < greater of 10% of line cap and $135mm.

Sheet Risk Rating
A1: Internal Risk Rating Scorecard
A2: Score 1 (strongest) to 5 (weakest). Quantitative scores come from the metrics; qualitative scores are analyst judgment (blue).
A4: Factor | B4: Metric / basis | C4: Score (1–5) | D4: Weight | E4: Weighted | F4: Rationale
A5: Leverage: net debt / EBITDA (LTM) | B5: ='Credit Metrics'!E14 -> 7.4635083 | C5: =IF(B5<=2,1,IF(B5<=3,2,IF(B5<=4,3,IF(B5<=5.5,4,5)))) -> 5 | D5: 0.25 | E5: =C5*D5 -> 1.25 | F5: LTM EBITDA fell with the U.S. demand slump; leverage far above the 3.0x guideline
A6: Coverage: EBITDA / interest (LTM) | B6: ='Credit Metrics'!E18 -> 2.4637224 | C6: =IF(B6>=8,1,IF(B6>=5,2,IF(B6>=3,3,IF(B6>=2,4,5)))) -> 4 | D6: 0.2 | E6: =C6*D6 -> 0.8 | F6: Below the legacy 3.0x covenant; new secured notes raise run-rate interest
A7: Cash flow: FCF / debt (FY2026E base) | B7: =Projections!C34 -> 0.043361746 | C7: =IF(B7>=0.2,1,IF(B7>=0.1,2,IF(B7>=0.05,3,IF(B7>=0,4,5)))) -> 4 | D7: 0.1 | E7: =C7*D7 -> 0.4 | F7: Positive but thin; heavy first-half seasonal cash outflow
A8: Liquidity | B8: Refinanced; ABL + cash | C8: 2 | D8: 0.15 | E8: =C8*D8 -> 0.3 | F8: June 2026 refinancing removed near-term maturities; next bond maturity Feb 2029
A9: Business profile | B9: Market leader, cyclical | C9: 3 | D9: 0.2 | E9: =C9*D9 -> 0.6 | F9: #1 North American appliance maker with strong brands, but exposed to housing, tariffs and price competition
A10: Financial policy | B10: Dividend maintained | C10: 3 | D10: 0.1 | E10: =C10*D10 -> 0.3 | F10: Dividend cut in 2025 but still ~$200mm a year while leverage is high
A11: Weighted obligor score | D11: =SUM(D5:D10) -> 1 | E11: =SUM(E5:E10) -> 3.65
A13: RATING OUTCOME
A14: Obligor risk rating (1–9 scale) | B14: =IF(E11<1.5,2,IF(E11<2,3,IF(E11<2.5,4,IF(E11<3,5,IF(E11<3.5,6,IF(E11<4,7,IF(E11<4.5,8,9))))))) -> 7 | C14: =INDEX($B$19:$B$26,B14-1) -> Special mention
A15: Collateral notching for the ABL (recovery value / line cap) | B15: ='ABL Collateral'!B13 -> 1.1764706 | C15: =IF(B15>=1.3,-2,IF(B15>=1.1,-1,0)) -> -1 | F15: Lending is capped by the borrowing base, so recovery is measured against the line cap: ≥ 1.1x = one notch, ≥ 1.3x = two notches
A16: ABL facility risk rating | B16: =MAX(1,B14+C15) -> 6 | C16: =INDEX($B$19:$B$26,B16-1) -> Pass — watch
A18: Rating scale
A19: 2 | B19: Pass — strong
A20: 3 | B20: Pass — good
A21: 4 | B21: Pass — satisfactory
A22: 5 | B22: Pass — acceptable
A23: 6 | B23: Pass — watch
A24: 7 | B24: Special mention
A25: 8 | B25: Substandard
A26: 9 | B26: Doubtful

Sheet Sources
A1: Sources
A3: FY2024–FY2025 financial statements, ongoing EBIT, 2026 guidance | B3: https://s202.q4cdn.com/229739679/files/doc_financials/2025/q4/12-31-2025-Press-Release.pdf
A4: FY2023 financial statements and ongoing EBIT reconciliation | B4: https://www.sec.gov/Archives/edgar/data/106640/000010664025000006/exhibit991pressrelease1231.htm
A5: Q1 2026 results | B5: https://whirlpool.mediaroom.com/2026-05-06-Whirlpool-Corporation-Announces-First-Quarter-Results-Accelerates-Cost-and-Pricing-Actions-to-Restore-Margins
A6: Q2 2026 results, June 30, 2026 balance sheet, updated 2026 guidance | B6: https://whirlpool.mediaroom.com/2026-08-03-Whirlpool-Corporation-Announces-Second-Quarter-Results
A7: Q1 2026 10-Q: credit facility, 3.0x interest coverage covenant, May 2026 amendment | B7: https://s202.q4cdn.com/229739679/files/doc_financials/2026/q1/90123cfc-fcc9-47d5-bf63-a4a60608339c.pdf
A8: 8-K (June 16, 2026): $2.0B second-lien notes and $2.0B ABL facility | B8: https://www.stocktitan.net/sec-filings/WHR/8-k-whirlpool-corp-de-reports-material-event-798b4b9d9771.html
A9: Bond prices, yields and ratings (Oct 15–16, 2026) | B9: https://bondterminal.com/issuers/whirlpool-corporation
A10: FY2025 Form 10-K: rating history and covenant risk factor | B10: https://www.sec.gov/Archives/edgar/data/106640/000010664026000009/whr-20251231.htm
A11: Dividend declaration ($0.90 per quarter, Feb 2026) | B11: https://www.stocktitan.net/news/WHR/whirlpool-corporation-declares-quarterly-yk8b10dyligh.html
A12: S&P, Moody's and Fitch 2025 rating actions | B12: https://ts2.tech/en/whirlpool-stock-nyse-whr-on-dec-19-2025-credit-downgrade-itc-patent-fight-india-stake-sale-dividend-outlook-and-2026-forecasts/
